import pytest
from django.core.exceptions import ValidationError
from api.proveedores.models import Proveedor  # Ajusta 'mi_app' por el nombre real de tu app

class ProveedorTestCase:

    def setUp(self):
        # Datos v치lidos para un Proveedor
        self.data_valida = {
            'tipo_persona': 'natural',
            'nombre_empresa': 'Empresa XYZ',
            'nit': '1234567890',
            'nombre': 'Juan Perez',
            'direccion': 'Calle Falsa 123',
            'correo_electronico': 'juan@example.com',
            'celular': '+12345678901',
            'estado': 'activo',
        }

    @pytest.mark.django_db
    def test_crear_proveedor_valido(self):
        proveedor = Proveedor(**self.data_valida)
        try:
            # full_clean valida los campos, sin guardar en DB
            proveedor.full_clean()
        except ValidationError:
            pytest.fail("full_clean() lanz칩 ValidationError con datos v치lidos")

    @pytest.mark.django_db
    def test_celular_invalido(self):
        datos = self.data_valida.copy()
        datos['celular'] = '123456'  # formato celular inv치lido
        proveedor = Proveedor(**datos)
        with pytest.raises(ValidationError):
            proveedor.full_clean()

    def test_str_retorna_nombre_empresa_y_nit(self):
        proveedor = Proveedor(**self.data_valida)
        esperado = f"{self.data_valida['nombre_empresa']} ({self.data_valida['nit']})"
        assert str(proveedor) == esperado



